<?xml version="1.0" ?>
<robot name="robot">
    <link name="base_link">
        <visual>
            <origin xyz=" 0 0 0" rpy="0 0 0" />
            <geometry>
                <box size="0.6 0.5 0.2"/>
            </geometry>
            <material name="yellow">
                <color rgba="1 0.1 0 1"/>
            </material>
        </visual>
    </link>    

    <joint name="left_wheel_joint" type="continuous">
        <origin xyz="0 0.25 -0.05" rpy="0 0 0"/>
        <parent link="base_link"/>
        <child link="left_wheel_link"/>
        <axis xyz="0 1 0"/>
    </joint>

    <link name="left_wheel_link">
        <visual>
            <origin xyz="0 0 0" rpy="1.5707 0 0" />
            <geometry>
                <cylinder radius="0.125" length = "0.04"/>
            </geometry>
            <material name="white">
                <color rgba="1 0.6 0 0.9"/>
            </material>
        </visual>
    </link>

    <joint name="right_wheel_joint" type="continuous">
        <origin xyz="0 -0.25 -0.05" rpy="0 0 0"/>
        <parent link="base_link"/>
        <child link="right_wheel_link"/>
        <axis xyz="0 1 0"/>
    </joint>

    <link name="right_wheel_link">
        <visual>
            <origin xyz="0 0 0" rpy="1.5707 0 0" />
            <geometry>
                <cylinder radius="0.125" length = "0.04"/>
            </geometry>
            <material name="white">
                <color rgba="1 0.6 1 0.9"/>
            </material>
        </visual>
    </link>

    <joint name="front_caster_joint" type="continuous">
        <origin xyz="0.2 0 -0.1" rpy="0 0 0"/>
        <parent link="base_link"/>
        <child link="front_caster_link"/>
        <axis xyz="0 1 0"/>
    </joint>

    <link name="front_caster_link">
        <visual>
            <origin xyz="0 0 0" rpy="0 0 0"/>
            <geometry>
                <sphere radius="0.075" />
            </geometry>
            <material name="yellow">
                <color rgba="1 1 0 1"/>
            </material>
        </visual>
    </link>
    
    <joint name="back_caster_joint" type="continuous">
        <origin xyz="-0.2 0 -0.1" rpy="0 0 0"/>
        <parent link="base_link"/>
        <child link="back_caster_link"/>
        <axis xyz="0 1 0"/>
    </joint>

    <link name="back_caster_link">
        <visual>
            <origin xyz="0 0 0" rpy="0 0 0"/>
            <geometry>
                <sphere radius="0.075" />
            </geometry>
            <material name="yellow">
                <color rgba="1 1 0 1"/>
            </material>
        </visual>
    </link>
    

    <joint name="lift1_joint" type="fixed">
        <origin xyz="0 0 0.35" rpy="0 0 0"/>
        <parent link="base_link"/>
        <child link="lift1_link"/>
        <axis xyz="0 0 1"/>
    </joint>

    <link name="lift1_link">
        <visual>
            <origin xyz="0 0 0" rpy="0 0 0" />
            <geometry>
                <cylinder radius="0.1" length = "0.5"/>
            </geometry>
            <material name="red">
                <color rgba="1 0.1 0 0.9"/>
            </material>
        </visual>
    </link>
    
    <joint name="lift2_joint" type="prismatic">
        <origin xyz="0 0 0.35" rpy="0 0 0"/>
        <parent link="base_link"/>
        <child link="lift2_link"/>
        <axis xyz="0 0 1"/>
        <limit lower="0"
               upper="0.46"
               effort="0"
               velocity="0.1" />
     </joint>

    <link name="lift2_link">
        <visual>
            <origin xyz="0 0 0" rpy="0 0 0" />
            <geometry>
                <cylinder radius="0.05" length = "0.5"/>
            </geometry>
            <material name="red">
                <color rgba="1 0.1 0 0.9"/>
            </material>
        </visual>
    </link>

    <joint name="camera_joint" type="fixed">
        <origin xyz="0 0 0.25" rpy="0 0 0"/>
        <parent link="lift2_link"/>
        <child link="camera_link"/>
        <axis xyz="0 0 1"/>
    </joint>

    <link name="camera_link">
        <visual>
            <origin xyz="0 0 0" rpy="0 0 0" />
            <geometry>
                <box size="0.2 0.05 0.05"/>
            </geometry>
            <material name="black">
                <color rgba="0 0 0 0.9"/>
            </material>
        </visual>
    </link>
    

</robot>